Workbook

Sheet Cover
B2: ROYAL ENFIELD | C2: ROYAL ENFIELD | D2: ROYAL ENFIELD | E2: ROYAL ENFIELD | F2: ROYAL ENFIELD | G2: ROYAL ENFIELD | H2: ROYAL ENFIELD | I2: ROYAL ENFIELD | J2: ROYAL ENFIELD | K2: ROYAL ENFIELD
B3: Integrated Scenario Planning Model | FY23 Actuals + FY24 Plan | C3: Integrated Scenario Planning Model | FY23 Actuals + FY24 Plan | D3: Integrated Scenario Planning Model | FY23 Actuals + FY24 Plan | E3: Integrated Scenario Planning Model | FY23 Actuals + FY24 Plan | F3: Integrated Scenario Planning Model | FY23 Actuals + FY24 Plan | G3: Integrated Scenario Planning Model | FY23 Actuals + FY24 Plan | H3: Integrated Scenario Planning Model | FY23 Actuals + FY24 Plan | I3: Integrated Scenario Planning Model | FY23 Actuals + FY24 Plan | J3: Integrated Scenario Planning Model | FY23 Actuals + FY24 Plan | K3: Integrated Scenario Planning Model | FY23 Actuals + FY24 Plan
B4: Revenue · Employee Cost · Marketing · P&L Summary | 3-Scenario Toggle | C4: Revenue · Employee Cost · Marketing · P&L Summary | 3-Scenario Toggle | D4: Revenue · Employee Cost · Marketing · P&L Summary | 3-Scenario Toggle | E4: Revenue · Employee Cost · Marketing · P&L Summary | 3-Scenario Toggle | F4: Revenue · Employee Cost · Marketing · P&L Summary | 3-Scenario Toggle | G4: Revenue · Employee Cost · Marketing · P&L Summary | 3-Scenario Toggle | H4: Revenue · Employee Cost · Marketing · P&L Summary | 3-Scenario Toggle | I4: Revenue · Employee Cost · Marketing · P&L Summary | 3-Scenario Toggle | J4: Revenue · Employee Cost · Marketing · P&L Summary | 3-Scenario Toggle | K4: Revenue · Employee Cost · Marketing · P&L Summary | 3-Scenario Toggle
B8: MODEL OVERVIEW | C8: MODEL OVERVIEW | D8: MODEL OVERVIEW | E8: MODEL OVERVIEW | F8: MODEL OVERVIEW | G8: MODEL OVERVIEW | H8: MODEL OVERVIEW | I8: MODEL OVERVIEW | J8: MODEL OVERVIEW
B9: This model integrates data from 9 source files into a unified FP&A planning workbook. | C9: This model integrates data from 9 source files into a unified FP&A planning workbook. | D9: This model integrates data from 9 source files into a unified FP&A planning workbook. | E9: This model integrates data from 9 source files into a unified FP&A planning workbook. | F9: This model integrates data from 9 source files into a unified FP&A planning workbook. | G9: This model integrates data from 9 source files into a unified FP&A planning workbook. | H9: This model integrates data from 9 source files into a unified FP&A planning workbook. | I9: This model integrates data from 9 source files into a unified FP&A planning workbook. | J9: This model integrates data from 9 source files into a unified FP&A planning workbook.
B10: Select your scenario on the Assumptions tab to drive volume and price projections. | C10: Select your scenario on the Assumptions tab to drive volume and price projections. | D10: Select your scenario on the Assumptions tab to drive volume and price projections. | E10: Select your scenario on the Assumptions tab to drive volume and price projections. | F10: Select your scenario on the Assumptions tab to drive volume and price projections. | G10: Select your scenario on the Assumptions tab to drive volume and price projections. | H10: Select your scenario on the Assumptions tab to drive volume and price projections. | I10: Select your scenario on the Assumptions tab to drive volume and price projections. | J10: Select your scenario on the Assumptions tab to drive volume and price projections.
B12: Sheet | C12: Description | D12: Source Files | E12: Source Files | F12: Source Files | G12: Source Files
B13: Assumptions | C13: Scenario inputs — volume growth, price change, marketing spend % | D13: Manual inputs | E13: Manual inputs | F13: Manual inputs | G13: Manual inputs
B14: Product_Master | C14: 5-level product hierarchy: Platform → Family → Index Key → Material | D14: Files 1, 2 | E14: Files 1, 2 | F14: Files 1, 2 | G14: Files 1, 2
B15: Price_NSP | C15: NSP (factory price), Ex-Showroom and On-Road price by Model Family | D15: File 3 | E15: File 3 | F15: File 3 | G15: File 3
B16: Volume_Plan | C16: Monthly volumes FY23 actuals + FY24 plan by Family × Zone | D16: File 11 | E16: File 11 | F16: File 11 | G16: File 11
B17: Revenue | C17: Revenue = Volume × NSP with scenario price adjustment | D17: Files 3, 11 | E17: Files 3, 11 | F17: Files 3, 11 | G17: Files 3, 11
B18: Emp_Cost | C18: Headcount × Planning Rate model with monthly additions / attritions | D18: File 8 | E18: File 8 | F18: File 8 | G18: File 8
B19: Mktng_Cost | C19: Marketing spend plan by activity IO, model family, monthly phasing | D19: File 4 | E19: File 4 | F19: File 4 | G19: File 4
B20: GL_Reference | C20: GL account hierarchy mapping to P&L and Balance Sheet nodes | D20: Files 9, 10 | E20: Files 9, 10 | F20: Files 9, 10 | G20: Files 9, 10
B21: P&L | C21: Monthly P&L: Gross Revenue → EBITDA with 3-scenario toggle | D21: All files | E21: All files | F21: All files | G21: All files
B24: COLOUR LEGEND | C24: COLOUR LEGEND | D24: COLOUR LEGEND | E24: COLOUR LEGEND
B25: ██ | C25: Hardcoded Input (Blue text) — change these to model scenarios | D25: Hardcoded Input (Blue text) — change these to model scenarios | E25: Hardcoded Input (Blue text) — change these to model scenarios | F25: Hardcoded Input (Blue text) — change these to model scenarios | G25: Hardcoded Input (Blue text) — change these to model scenarios
B26: ██ | C26: Formula / Calculation (Black text) | D26: Formula / Calculation (Black text) | E26: Formula / Calculation (Black text) | F26: Formula / Calculation (Black text) | G26: Formula / Calculation (Black text)
B27: ██ | C27: Cross-sheet Link (Green text) | D27: Cross-sheet Link (Green text) | E27: Cross-sheet Link (Green text) | F27: Cross-sheet Link (Green text) | G27: Cross-sheet Link (Green text)
B28: ██ | C28: External file link (Red text) | D28: External file link (Red text) | E28: External file link (Red text) | F28: External file link (Red text) | G28: External file link (Red text)

Sheet Assumptions
A1: ROYAL ENFIELD | SCENARIO ASSUMPTIONS | B1: ROYAL ENFIELD | SCENARIO ASSUMPTIONS | C1: ROYAL ENFIELD | SCENARIO ASSUMPTIONS | D1: ROYAL ENFIELD | SCENARIO ASSUMPTIONS | E1: ROYAL ENFIELD | SCENARIO ASSUMPTIONS | F1: ROYAL ENFIELD | SCENARIO ASSUMPTIONS | G1: ROYAL ENFIELD | SCENARIO ASSUMPTIONS | H1: ROYAL ENFIELD | SCENARIO ASSUMPTIONS
A3: SCENARIO SELECTOR | B3: SCENARIO SELECTOR | C3: SCENARIO SELECTOR
A4: Active Scenario | B4: Base | C4: ← Select: Base / Bull / Bear
A6: VOLUME GROWTH ASSUMPTIONS (YoY FY24 vs FY23) | B6: VOLUME GROWTH ASSUMPTIONS (YoY FY24 vs FY23) | C6: VOLUME GROWTH ASSUMPTIONS (YoY FY24 vs FY23) | D6: VOLUME GROWTH ASSUMPTIONS (YoY FY24 vs FY23) | E6: VOLUME GROWTH ASSUMPTIONS (YoY FY24 vs FY23) | F6: VOLUME GROWTH ASSUMPTIONS (YoY FY24 vs FY23) | G6: VOLUME GROWTH ASSUMPTIONS (YoY FY24 vs FY23) | H6: VOLUME GROWTH ASSUMPTIONS (YoY FY24 vs FY23)
A7: Model Family | B7: Base Growth % | C7: Bull Growth % | D7: Bear Growth % | E7: Active Growth % | F7: Note
A8: Bullet | B8: 0.06 | C8: 0.15 | D8: -0.05 | E8: =IF(Assumptions!$B$4="Bull",C8,IF(Assumptions!$B$4="Bear",D8,B8)) -> 0.06 | F8: Base = consensus; Bull = strong demand; Bear = macro headwinds
A9: Classic | B9: 0.05 | C9: 0.12 | D9: -0.04 | E9: =IF(Assumptions!$B$4="Bull",C9,IF(Assumptions!$B$4="Bear",D9,B9)) -> 0.05 | F9: Base = consensus; Bull = strong demand; Bear = macro headwinds
A10: Himalayan | B10: 0.1 | C10: 0.2 | D10: -0.03 | E10: =IF(Assumptions!$B$4="Bull",C10,IF(Assumptions!$B$4="Bear",D10,B10)) -> 0.1 | F10: Base = consensus; Bull = strong demand; Bear = macro headwinds
A11: Meteor | B11: 0.08 | C11: 0.18 | D11: -0.06 | E11: =IF(Assumptions!$B$4="Bull",C11,IF(Assumptions!$B$4="Bear",D11,B11)) -> 0.08 | F11: Base = consensus; Bull = strong demand; Bear = macro headwinds
A12: Twins | B12: 0.12 | C12: 0.22 | D12: 0 | E12: =IF(Assumptions!$B$4="Bull",C12,IF(Assumptions!$B$4="Bear",D12,B12)) -> 0.12 | F12: Base = consensus; Bull = strong demand; Bear = macro headwinds
A14: PRICE (NSP) CHANGE ASSUMPTIONS (% change vs current NSP) | B14: PRICE (NSP) CHANGE ASSUMPTIONS (% change vs current NSP) | C14: PRICE (NSP) CHANGE ASSUMPTIONS (% change vs current NSP) | D14: PRICE (NSP) CHANGE ASSUMPTIONS (% change vs current NSP) | E14: PRICE (NSP) CHANGE ASSUMPTIONS (% change vs current NSP) | F14: PRICE (NSP) CHANGE ASSUMPTIONS (% change vs current NSP) | G14: PRICE (NSP) CHANGE ASSUMPTIONS (% change vs current NSP) | H14: PRICE (NSP) CHANGE ASSUMPTIONS (% change vs current NSP)
A15: Model Family | B15: Base Price Δ% | C15: Bull Price Δ% | D15: Bear Price Δ% | E15: Active Price Δ% | F15: Note
A16: Bullet | B16: 0.02 | C16: 0.05 | D16: 0 | E16: =IF(Assumptions!$B$4="Bull",C16,IF(Assumptions!$B$4="Bear",D16,B16)) -> 0.02 | F16: Reflects planned price revision announcements
A17: Classic | B17: 0.02 | C17: 0.04 | D17: 0 | E17: =IF(Assumptions!$B$4="Bull",C17,IF(Assumptions!$B$4="Bear",D17,B17)) -> 0.02 | F17: Reflects planned price revision announcements
A18: Himalayan | B18: 0.03 | C18: 0.06 | D18: 0.01 | E18: =IF(Assumptions!$B$4="Bull",C18,IF(Assumptions!$B$4="Bear",D18,B18)) -> 0.03 | F18: Reflects planned price revision announcements
A19: Meteor | B19: 0.02 | C19: 0.05 | D19: 0 | E19: =IF(Assumptions!$B$4="Bull",C19,IF(Assumptions!$B$4="Bear",D19,B19)) -> 0.02 | F19: Reflects planned price revision announcements
A20: Twins | B20: 0.02 | C20: 0.04 | D20: 0.01 | E20: =IF(Assumptions!$B$4="Bull",C20,IF(Assumptions!$B$4="Bear",D20,B20)) -> 0.02 | F20: Reflects planned price revision announcements
A22: COST ASSUMPTIONS | B22: COST ASSUMPTIONS | C22: COST ASSUMPTIONS | D22: COST ASSUMPTIONS | E22: COST ASSUMPTIONS | F22: COST ASSUMPTIONS | G22: COST ASSUMPTIONS | H22: COST ASSUMPTIONS
A23: Cost Item | B23: Base | C23: Bull | D23: Bear | E23: Active | F23: Note
A24: Material Cost % of NSP | B24: 0.6 | C24: 0.58 | D24: 0.62 | E24: =IF(Assumptions!$B$4="Bull",C24,IF(Assumptions!$B$4="Bear",D24,B24)) -> 0.6 | F24: Vehicle materials, components — COGS
A25: Marketing Spend % of Revenue | B25: 0.04 | C25: 0.05 | D25: 0.035 | E25: =IF(Assumptions!$B$4="Bull",C25,IF(Assumptions!$B$4="Bear",D25,B25)) -> 0.04 | F25: IO-level spend across activities
A26: Other Overheads (INR Cr/mo) | B26: 18 | C26: 20 | D26: 15 | E26: =IF(Assumptions!$B$4="Bull",C26,IF(Assumptions!$B$4="Bear",D26,B26)) -> 18 | F26: Fixed overheads (manufacturing, G&A)

Sheet Product_Master
A1: PRODUCT HIERARCHY MASTER | Source: Files 1 & 2 — RE Masters, Product Hierarchy | B1: PRODUCT HIERARCHY MASTER | Source: Files 1 & 2 — RE Masters, Product Hierarchy | C1: PRODUCT HIERARCHY MASTER | Source: Files 1 & 2 — RE Masters, Product Hierarchy | D1: PRODUCT HIERARCHY MASTER | Source: Files 1 & 2 — RE Masters, Product Hierarchy | E1: PRODUCT HIERARCHY MASTER | Source: Files 1 & 2 — RE Masters, Product Hierarchy | F1: PRODUCT HIERARCHY MASTER | Source: Files 1 & 2 — RE Masters, Product Hierarchy
A2: Platform | B2: Family | C2: Index Key | D2: Variant Description | E2: Material Group | F2: Notes
A3: UCE | B3: Bullet | C3: 101 | D3: Bullet 350 (Single Channel) BSVI | E3: 6001
A4: UCE | B4: Bullet | C4: 103 | D4: Bullet ES X (Single Channel) BSVI | E4: 6002C
A5: J | B5: Hunter | C5: 126 | D5: Hunter 350 Single Channel | E5: 6004D
A6: UCE | B6: Bullet UCE | C6: V101 | D6: Bullet 350 (Single Channel) BSVI | E6: 6001
A7: UCE | B7: Bullet UCE | C7: V102 | D7: Bullet X (Single Channel) BSVI | E7: 6001A
A8: UCE | B8: Bullet UCE | C8: V103 | D8: Bullet ES X (Single Channel) BSVI | E8: 6002
A9: J | B9: Hunter | C9: V126 | D9: Hunter 350 Single Channel | E9: 6004D
A10: J | B10: Hunter | C10: V127 | D10: Hunter 350 Dual Channel Base | E10: 6004000000000
A11: J | B11: Hunter | C11: V178 | D11: Hunter 350 Dual Channel Premium | E11: 6004C
A12: J | B12: Classic J1A | C12: V160 | D12: New Classic Redditch (Single Channel) | E12: 6005Q
A13: J | B13: Classic J1A | C13: V181 | D13: New Classic Halcyon (Single Channel) | E13: 6005S
A14: J | B14: Classic J1A | C14: V120 | D14: New Classic Halcyon (Dual Channel) | E14: 6005J
A15: J | B15: Classic J1A | C15: V121 | D15: New Classic Signals (Dual Channel) | E15: 600500000
A16: J | B16: Classic J1A | C16: V122 | D16: New Classic Dark (Dual Channel) | E16: 6005000000
A17: J | B17: Classic J1A | C17: V123 | D17: New Classic Chrome (Dual Channel) | E17: 6005000
A18: J | B18: Meteor | C18: V128 | D18: Meteor Fireball (Dual Channel) | E18: 6003000000000
A19: J | B19: Meteor | C19: V129 | D19: Meteor Stellar (Dual Channel) | E19: 6003C
A20: J | B20: Meteor | C20: V130 | D20: Meteor Supernova (Dual Channel) | E20: 6003D
A21: D | B21: Himalayan | C21: V166 | D21: Himalayan D3G Mid | E21: 6020D
A22: D | B22: Himalayan | C22: V113 | D22: Himalayan D3G Premium | E22: 6020E
A23: D | B23: Himalayan | C23: V167 | D23: Himalayan D3G Base | E23: 6020A
A24: D | B24: Scram | C24: V169 | D24: Scram 411 D3K Mid | E24: 6020F
A25: D | B25: Scram | C25: V170 | D25: Scram 411 D3K Premium | E25: 6020G
A26: D | B26: Scram | C26: V168 | D26: Scram 411 D3K Base | E26: 6020C
A27: P | B27: Twins 650 | C27: V114 | D27: Interceptor 650 Base | E27: 6022
A28: P | B28: Twins 650 | C28: V115 | D28: Interceptor 650 Mid | E28: 6022A
A29: P | B29: Twins 650 | C29: V116 | D29: Interceptor 650 Premium | E29: 6022D
A30: P | B30: Twins 650 | C30: V117 | D30: Continental 650 Base | E30: 6010A
A31: P | B31: Twins 650 | C31: V118 | D31: Continental 650 Mid | E31: 6010C
A32: P | B32: Twins 650 | C32: V119 | D32: Continental 650 Premium | E32: 6010E
A33: UCE | B33: Classic UCE | C33: V104 | D33: Classic 350 (Single Channel) BSVI | E33: 6005000000000
A34: UCE | B34: Classic UCE | C34: V140 | D34: Classic 350 (Dual Channel) BSVI | E34: 6005
A35: UCE | B35: Classic UCE | C35: V105 | D35: Classic 350 Signal (Dual Channel) BSVI | E35: 6005E
A36: UCE | B36: Classic UCE | C36: V106 | D36: Classic 350 Chrome (Dual Channel) BSVI | E36: 6005FA
A37: UCE | B37: Classic UCE | C37: V161 | D37: Classic 350 Gun Grey Spoke (Dual Channel) BSVI | E37: 6005A
A38: UCE | B38: Classic UCE | C38: V107 | D38: Classic 350 Gun Grey Alloy (Dual Channel) BSVI | E38: 6005AB
A39: UCE | B39: Classic UCE | C39: V108 | D39: Classic 350 Stealth Black Alloy (Dual Channel) BSVI | E39: 6005G
A40: Sl No | B40: Total Domestic Unique Index Key's for delta | C40: Total International Unique Index Key's for delta
...

Sheet Price_NSP
A1: NSP & PRICE WALK BY MODEL FAMILY | Source: File 3 — MTS Price Working (avg. across 2,482 model-state combinations) | B1: NSP & PRICE WALK BY MODEL FAMILY | Source: File 3 — MTS Price Working (avg. across 2,482 model-state combinations) | C1: NSP & PRICE WALK BY MODEL FAMILY | Source: File 3 — MTS Price Working (avg. across 2,482 model-state combinations) | D1: NSP & PRICE WALK BY MODEL FAMILY | Source: File 3 — MTS Price Working (avg. across 2,482 model-state combinations) | E1: NSP & PRICE WALK BY MODEL FAMILY | Source: File 3 — MTS Price Working (avg. across 2,482 model-state combinations) | F1: NSP & PRICE WALK BY MODEL FAMILY | Source: File 3 — MTS Price Working (avg. across 2,482 model-state combinations) | G1: NSP & PRICE WALK BY MODEL FAMILY | Source: File 3 — MTS Price Working (avg. across 2,482 model-state combinations) | H1: NSP & PRICE WALK BY MODEL FAMILY | Source: File 3 — MTS Price Working (avg. across 2,482 model-state combinations) | I1: NSP & PRICE WALK BY MODEL FAMILY | Source: File 3 — MTS Price Working (avg. across 2,482 model-state combinations)
A2: Model Family | B2: NSP (₹) | C2: GST Rate | D2: GST Amount (₹) | E2: Ex-Showroom (₹) | F2: RTO+Ins (₹) | G2: On-Road (₹) | H2: NSP/On-Road % | I2: FY24 Adj NSP (₹)
A3: Bullet | B3: 112168 | C3: 0.14 | D3: =B3*C3*2 -> 31407.04 | E3: 156480 | F3: =E3-D3-B3 -> 12904.96 | G3: 177367 | H3: =IFERROR(B3/G3,"-") -> 0.63240625 | I3: =B3*(1+VLOOKUP(A3,Assumptions!$A$16:$E$20,5,0)) -> 114411.36
A4: Classic | B4: 147156 | C4: 0.14 | D4: =B4*C4*2 -> 41203.68 | E4: 202960 | F4: =E4-D4-B4 -> 14600.32 | G4: 227974 | H4: =IFERROR(B4/G4,"-") -> 0.64549466 | I4: =B4*(1+VLOOKUP(A4,Assumptions!$A$16:$E$20,5,0)) -> 150099.12
A5: Meteor | B5: 152511 | C5: 0.14 | D5: =B5*C5*2 -> 42703.08 | E5: 210106 | F5: =E5-D5-B5 -> 14891.92 | G5: 235877 | H5: =IFERROR(B5/G5,"-") -> 0.64657003 | I5: =B5*(1+VLOOKUP(A5,Assumptions!$A$16:$E$20,5,0)) -> 155561.22
A6: Himalayan | B6: 152219 | C6: 0.14 | D6: =B6*C6*2 -> 42621.32 | E6: 214941 | F6: =E6-D6-B6 -> 20100.68 | G6: 250318 | H6: =IFERROR(B6/G6,"-") -> 0.60810249 | I6: =B6*(1+VLOOKUP(A6,Assumptions!$A$16:$E$20,5,0)) -> 156785.57
A7: Twins | B7: 214564 | C7: 0.14 | D7: =B7*C7*2 -> 60077.92 | E7: 303309 | F7: =E7-D7-B7 -> 28667.08 | G7: 346492 | H7: =IFERROR(B7/G7,"-") -> 0.61924662 | I7: =B7*(1+VLOOKUP(A7,Assumptions!$A$16:$E$20,5,0)) -> 218855.28
A9: Note: NSP = Net Selling Price (factory realisation). Values are weighted averages across all states. Blue = hardcoded input from source file. Teal = FY24 scenario-adjusted NSP. | B9: Note: NSP = Net Selling Price (factory realisation). Values are weighted averages across all states. Blue = hardcoded input from source file. Teal = FY24 scenario-adjusted NSP. | C9: Note: NSP = Net Selling Price (factory realisation). Values are weighted averages across all states. Blue = hardcoded input from source file. Teal = FY24 scenario-adjusted NSP. | D9: Note: NSP = Net Selling Price (factory realisation). Values are weighted averages across all states. Blue = hardcoded input from source file. Teal = FY24 scenario-adjusted NSP. | E9: Note: NSP = Net Selling Price (factory realisation). Values are weighted averages across all states. Blue = hardcoded input from source file. Teal = FY24 scenario-adjusted NSP. | F9: Note: NSP = Net Selling Price (factory realisation). Values are weighted averages across all states. Blue = hardcoded input from source file. Teal = FY24 scenario-adjusted NSP. | G9: Note: NSP = Net Selling Price (factory realisation). Values are weighted averages across all states. Blue = hardcoded input from source file. Teal = FY24 scenario-adjusted NSP. | H9: Note: NSP = Net Selling Price (factory realisation). Values are weighted averages across all states. Blue = hardcoded input from source file. Teal = FY24 scenario-adjusted NSP. | I9: Note: NSP = Net Selling Price (factory realisation). Values are weighted averages across all states. Blue = hardcoded input from source file. Teal = FY24 scenario-adjusted NSP.

Sheet Volume_Plan
A1: VOLUME PLAN | Source: File 11 — Volume Planning | FY23 Actuals + FY24 Scenario Plan (Units) | B1: VOLUME PLAN | Source: File 11 — Volume Planning | FY23 Actuals + FY24 Scenario Plan (Units) | C1: VOLUME PLAN | Source: File 11 — Volume Planning | FY23 Actuals + FY24 Scenario Plan (Units) | D1: VOLUME PLAN | Source: File 11 — Volume Planning | FY23 Actuals + FY24 Scenario Plan (Units) | E1: VOLUME PLAN | Source: File 11 — Volume Planning | FY23 Actuals + FY24 Scenario Plan (Units) | F1: VOLUME PLAN | Source: File 11 — Volume Planning | FY23 Actuals + FY24 Scenario Plan (Units) | G1: VOLUME PLAN | Source: File 11 — Volume Planning | FY23 Actuals + FY24 Scenario Plan (Units) | H1: VOLUME PLAN | Source: File 11 — Volume Planning | FY23 Actuals + FY24 Scenario Plan (Units) | I1: VOLUME PLAN | Source: File 11 — Volume Planning | FY23 Actuals + FY24 Scenario Plan (Units) | J1: VOLUME PLAN | Source: File 11 — Volume Planning | FY23 Actuals + FY24 Scenario Plan (Units) | K1: VOLUME PLAN | Source: File 11 — Volume Planning | FY23 Actuals + FY24 Scenario Plan (Units) | L1: VOLUME PLAN | Source: File 11 — Volume Planning | FY23 Actuals + FY24 Scenario Plan (Units) | M1: VOLUME PLAN | Source: File 11 — Volume Planning | FY23 Actuals + FY24 Scenario Plan (Units) | N1: VOLUME PLAN | Source: File 11 — Volume Planning | FY23 Actuals + FY24 Scenario Plan (Units) | O1: VOLUME PLAN | Source: File 11 — Volume Planning | FY23 Actuals + FY24 Scenario Plan (Units) | P1: VOLUME PLAN | Source: File 11 — Volume Planning | FY23 Actuals + FY24 Scenario Plan (Units)
A2: Model Family | B2: Metric | C2: Apr-23 | D2: May-23 | E2: Jun-23 | F2: Jul-23 | G2: Aug-23 | H2: Sep-23 | I2: Oct-23 | J2: Nov-23 | K2: Dec-23 | L2: Jan-24 | M2: Feb-24 | N2: Mar-24 | O2: FY Total | P2: YoY Δ%
A3: ▶ FY23 ACTUAL VOLUMES (Apr-23 to Mar-24, India Domestic) | B3: ▶ FY23 ACTUAL VOLUMES (Apr-23 to Mar-24, India Domestic) | C3: ▶ FY23 ACTUAL VOLUMES (Apr-23 to Mar-24, India Domestic) | D3: ▶ FY23 ACTUAL VOLUMES (Apr-23 to Mar-24, India Domestic) | E3: ▶ FY23 ACTUAL VOLUMES (Apr-23 to Mar-24, India Domestic) | F3: ▶ FY23 ACTUAL VOLUMES (Apr-23 to Mar-24, India Domestic) | G3: ▶ FY23 ACTUAL VOLUMES (Apr-23 to Mar-24, India Domestic) | H3: ▶ FY23 ACTUAL VOLUMES (Apr-23 to Mar-24, India Domestic) | I3: ▶ FY23 ACTUAL VOLUMES (Apr-23 to Mar-24, India Domestic) | J3: ▶ FY23 ACTUAL VOLUMES (Apr-23 to Mar-24, India Domestic) | K3: ▶ FY23 ACTUAL VOLUMES (Apr-23 to Mar-24, India Domestic) | L3: ▶ FY23 ACTUAL VOLUMES (Apr-23 to Mar-24, India Domestic) | M3: ▶ FY23 ACTUAL VOLUMES (Apr-23 to Mar-24, India Domestic) | N3: ▶ FY23 ACTUAL VOLUMES (Apr-23 to Mar-24, India Domestic) | O3: ▶ FY23 ACTUAL VOLUMES (Apr-23 to Mar-24, India Domestic) | P3: ▶ FY23 ACTUAL VOLUMES (Apr-23 to Mar-24, India Domestic)
A4: Bullet | B4: Actual Units | C4: 600000 | D4: 6300000 | E4: 47897 | F4: 58909 | G4: 48613 | H4: 47897 | I4: 58909 | J4: 48613 | K4: 53546 | L4: 54097 | M4: 54411 | N4: 55931 | O4: =SUM(C4:N4) -> 7428823 | P4: -
A5: Classic | B5: Actual Units | C5: 9931 | D5: 10998 | E5: 10999 | F5: 9931 | G5: 10998 | H5: 10999 | I5: 11638 | J5: 11763 | K5: 11752 | L5: 10669 | M5: 11457 | N5: 10856 | O5: =SUM(C5:N5) -> 131991 | P5: -
A6: Himalayan | B6: Actual Units | C6: 28468 | D6: 34259 | E6: 25674 | F6: 28468 | G6: 34259 | H6: 25674 | I6: 32343 | J6: 28971 | K6: 33409 | L6: 32729 | M6: 28949 | N6: 33426 | O6: =SUM(C6:N6) -> 366629 | P6: -
A7: Meteor | B7: Actual Units | C7: 2651 | D7: 4743 | E7: 4396 | F7: 2651 | G7: 4743 | H7: 4396 | I7: 3966 | J7: 3294 | K7: 2592 | L7: 2534 | M7: 2931 | N7: 2949 | O7: =SUM(C7:N7) -> 41846 | P7: -
A8: Twins | B8: Actual Units | C8: 4929 | D8: 6609 | E8: 5355 | F8: 4929 | G8: 6609 | H8: 5355 | I8: 4184 | J8: 7760 | K8: 4861 | L8: 8171 | M8: 6664 | N8: 8129 | O8: =SUM(C8:N8) -> 73555 | P8: -
A9: FY23 TOTAL | B9: FY23 TOTAL | C9: =SUM(C4:C8) -> 645979 | D9: =SUM(D4:D8) -> 6356609 | E9: =SUM(E4:E8) -> 94321 | F9: =SUM(F4:F8) -> 104888 | G9: =SUM(G4:G8) -> 105222 | H9: =SUM(H4:H8) -> 94321 | I9: =SUM(I4:I8) -> 111040 | J9: =SUM(J4:J8) -> 100401 | ... N9: =SUM(N4:N8) -> 111291 | O9: =SUM(C9:N9) -> 8042844
A11: ▶ FY24 PLAN VOLUMES (Apr-24 to Mar-25, Scenario-driven) | B11: ▶ FY24 PLAN VOLUMES (Apr-24 to Mar-25, Scenario-driven) | C11: ▶ FY24 PLAN VOLUMES (Apr-24 to Mar-25, Scenario-driven) | D11: ▶ FY24 PLAN VOLUMES (Apr-24 to Mar-25, Scenario-driven) | E11: ▶ FY24 PLAN VOLUMES (Apr-24 to Mar-25, Scenario-driven) | F11: ▶ FY24 PLAN VOLUMES (Apr-24 to Mar-25, Scenario-driven) | G11: ▶ FY24 PLAN VOLUMES (Apr-24 to Mar-25, Scenario-driven) | H11: ▶ FY24 PLAN VOLUMES (Apr-24 to Mar-25, Scenario-driven) | I11: ▶ FY24 PLAN VOLUMES (Apr-24 to Mar-25, Scenario-driven) | J11: ▶ FY24 PLAN VOLUMES (Apr-24 to Mar-25, Scenario-driven) | K11: ▶ FY24 PLAN VOLUMES (Apr-24 to Mar-25, Scenario-driven) | L11: ▶ FY24 PLAN VOLUMES (Apr-24 to Mar-25, Scenario-driven) | M11: ▶ FY24 PLAN VOLUMES (Apr-24 to Mar-25, Scenario-driven) | N11: ▶ FY24 PLAN VOLUMES (Apr-24 to Mar-25, Scenario-driven) | O11: ▶ FY24 PLAN VOLUMES (Apr-24 to Mar-25, Scenario-driven) | P11: ▶ FY24 PLAN VOLUMES (Apr-24 to Mar-25, Scenario-driven)
A12: Bullet | B12: Plan Units | C12: =ROUND(C4*(1+VLOOKUP(A12,Assumptions!$A$8:$E$12,5,0)),0) -> 636000 | D12: =ROUND(D4*(1+VLOOKUP(A12,Assumptions!$A$8:$E$12,5,0)),0) -> 6678000 | E12: =ROUND(E4*(1+VLOOKUP(A12,Assumptions!$A$8:$E$12,5,0)),0) -> 50771 | F12: =ROUND(F4*(1+VLOOKUP(A12,Assumptions!$A$8:$E$12,5,0)),0) -> 62444 | G12: =ROUND(G4*(1+VLOOKUP(A12,Assumptions!$A$8:$E$12,5,0)),0) -> 51530 | H12: =ROUND(H4*(1+VLOOKUP(A12,Assumptions!$A$8:$E$12,5,0)),0) -> 50771 | I12: =ROUND(I4*(1+VLOOKUP(A12,Assumptions!$A$8:$E$12,5,0)),0) -> 62444 | J12: =ROUND(J4*(1+VLOOKUP(A12,Assumptions!$A$8:$E$12,5,0)),0) -> 51530 | K12: =ROUND(K4*(1+VLOOKUP(A12,Assumptions!$A$8:$E$12,5,0)),0) -> 56759 | L12: =ROUND(L4*(1+VLOOKUP(A12,Assumptions!$A$8:$E$12,5,0)),0) -> 57343 | M12: =ROUND(M4*(1+VLOOKUP(A12,Assumptions!$A$8:$E$12,5,0)),0) -> 57676 | N12: =ROUND(N4*(1+VLOOKUP(A12,Assumptions!$A$8:$E$12,5,0)),0) -> 59287 | O12: =SUM(C12:N12) -> 7874555 | P12: =IFERROR(O12/O4-1,0) -> 0.060000353
A13: Classic | B13: Plan Units | C13: =ROUND(C5*(1+VLOOKUP(A13,Assumptions!$A$8:$E$12,5,0)),0) -> 10428 | D13: =ROUND(D5*(1+VLOOKUP(A13,Assumptions!$A$8:$E$12,5,0)),0) -> 11548 | E13: =ROUND(E5*(1+VLOOKUP(A13,Assumptions!$A$8:$E$12,5,0)),0) -> 11549 | F13: =ROUND(F5*(1+VLOOKUP(A13,Assumptions!$A$8:$E$12,5,0)),0) -> 10428 | G13: =ROUND(G5*(1+VLOOKUP(A13,Assumptions!$A$8:$E$12,5,0)),0) -> 11548 | H13: =ROUND(H5*(1+VLOOKUP(A13,Assumptions!$A$8:$E$12,5,0)),0) -> 11549 | I13: =ROUND(I5*(1+VLOOKUP(A13,Assumptions!$A$8:$E$12,5,0)),0) -> 12220 | J13: =ROUND(J5*(1+VLOOKUP(A13,Assumptions!$A$8:$E$12,5,0)),0) -> 12351 | K13: =ROUND(K5*(1+VLOOKUP(A13,Assumptions!$A$8:$E$12,5,0)),0) -> 12340 | L13: =ROUND(L5*(1+VLOOKUP(A13,Assumptions!$A$8:$E$12,5,0)),0) -> 11202 | M13: =ROUND(M5*(1+VLOOKUP(A13,Assumptions!$A$8:$E$12,5,0)),0) -> 12030 | N13: =ROUND(N5*(1+VLOOKUP(A13,Assumptions!$A$8:$E$12,5,0)),0) -> 11399 | O13: =SUM(C13:N13) -> 138592 | P13: =IFERROR(O13/O5-1,0) -> 0.050010986
A14: Himalayan | B14: Plan Units | C14: =ROUND(C6*(1+VLOOKUP(A14,Assumptions!$A$8:$E$12,5,0)),0) -> 31315 | D14: =ROUND(D6*(1+VLOOKUP(A14,Assumptions!$A$8:$E$12,5,0)),0) -> 37685 | E14: =ROUND(E6*(1+VLOOKUP(A14,Assumptions!$A$8:$E$12,5,0)),0) -> 28241 | F14: =ROUND(F6*(1+VLOOKUP(A14,Assumptions!$A$8:$E$12,5,0)),0) -> 31315 | G14: =ROUND(G6*(1+VLOOKUP(A14,Assumptions!$A$8:$E$12,5,0)),0) -> 37685 | H14: =ROUND(H6*(1+VLOOKUP(A14,Assumptions!$A$8:$E$12,5,0)),0) -> 28241 | I14: =ROUND(I6*(1+VLOOKUP(A14,Assumptions!$A$8:$E$12,5,0)),0) -> 35577 | J14: =ROUND(J6*(1+VLOOKUP(A14,Assumptions!$A$8:$E$12,5,0)),0) -> 31868 | K14: =ROUND(K6*(1+VLOOKUP(A14,Assumptions!$A$8:$E$12,5,0)),0) -> 36750 | L14: =ROUND(L6*(1+VLOOKUP(A14,Assumptions!$A$8:$E$12,5,0)),0) -> 36002 | M14: =ROUND(M6*(1+VLOOKUP(A14,Assumptions!$A$8:$E$12,5,0)),0) -> 31844 | N14: =ROUND(N6*(1+VLOOKUP(A14,Assumptions!$A$8:$E$12,5,0)),0) -> 36769 | O14: =SUM(C14:N14) -> 403292 | P14: =IFERROR(O14/O6-1,0) -> 0.10000027
A15: Meteor | B15: Plan Units | C15: =ROUND(C7*(1+VLOOKUP(A15,Assumptions!$A$8:$E$12,5,0)),0) -> 2863 | D15: =ROUND(D7*(1+VLOOKUP(A15,Assumptions!$A$8:$E$12,5,0)),0) -> 5122 | E15: =ROUND(E7*(1+VLOOKUP(A15,Assumptions!$A$8:$E$12,5,0)),0) -> 4748 | F15: =ROUND(F7*(1+VLOOKUP(A15,Assumptions!$A$8:$E$12,5,0)),0) -> 2863 | G15: =ROUND(G7*(1+VLOOKUP(A15,Assumptions!$A$8:$E$12,5,0)),0) -> 5122 | H15: =ROUND(H7*(1+VLOOKUP(A15,Assumptions!$A$8:$E$12,5,0)),0) -> 4748 | I15: =ROUND(I7*(1+VLOOKUP(A15,Assumptions!$A$8:$E$12,5,0)),0) -> 4283 | J15: =ROUND(J7*(1+VLOOKUP(A15,Assumptions!$A$8:$E$12,5,0)),0) -> 3558 | K15: =ROUND(K7*(1+VLOOKUP(A15,Assumptions!$A$8:$E$12,5,0)),0) -> 2799 | L15: =ROUND(L7*(1+VLOOKUP(A15,Assumptions!$A$8:$E$12,5,0)),0) -> 2737 | M15: =ROUND(M7*(1+VLOOKUP(A15,Assumptions!$A$8:$E$12,5,0)),0) -> 3165 | N15: =ROUND(N7*(1+VLOOKUP(A15,Assumptions!$A$8:$E$12,5,0)),0) -> 3185 | O15: =SUM(C15:N15) -> 45193 | P15: =IFERROR(O15/O7-1,0) -> 0.07998375
A16: Twins | B16: Plan Units | C16: =ROUND(C8*(1+VLOOKUP(A16,Assumptions!$A$8:$E$12,5,0)),0) -> 5520 | D16: =ROUND(D8*(1+VLOOKUP(A16,Assumptions!$A$8:$E$12,5,0)),0) -> 7402 | E16: =ROUND(E8*(1+VLOOKUP(A16,Assumptions!$A$8:$E$12,5,0)),0) -> 5998 | F16: =ROUND(F8*(1+VLOOKUP(A16,Assumptions!$A$8:$E$12,5,0)),0) -> 5520 | G16: =ROUND(G8*(1+VLOOKUP(A16,Assumptions!$A$8:$E$12,5,0)),0) -> 7402 | H16: =ROUND(H8*(1+VLOOKUP(A16,Assumptions!$A$8:$E$12,5,0)),0) -> 5998 | I16: =ROUND(I8*(1+VLOOKUP(A16,Assumptions!$A$8:$E$12,5,0)),0) -> 4686 | J16: =ROUND(J8*(1+VLOOKUP(A16,Assumptions!$A$8:$E$12,5,0)),0) -> 8691 | K16: =ROUND(K8*(1+VLOOKUP(A16,Assumptions!$A$8:$E$12,5,0)),0) -> 5444 | L16: =ROUND(L8*(1+VLOOKUP(A16,Assumptions!$A$8:$E$12,5,0)),0) -> 9152 | M16: =ROUND(M8*(1+VLOOKUP(A16,Assumptions!$A$8:$E$12,5,0)),0) -> 7464 | N16: =ROUND(N8*(1+VLOOKUP(A16,Assumptions!$A$8:$E$12,5,0)),0) -> 9104 | O16: =SUM(C16:N16) -> 82381 | P16: =IFERROR(O16/O8-1,0) -> 0.11999184
A17: FY24 TOTAL | B17: FY24 TOTAL | C17: =SUM(C12:C16) -> 686126 | D17: =SUM(D12:D16) -> 6739757 | E17: =SUM(E12:E16) -> 101307 | F17: =SUM(F12:F16) -> 112570 | G17: =SUM(G12:G16) -> 113287 | H17: =SUM(H12:H16) -> 101307 | I17: =SUM(I12:I16) -> 119210 | J17: =SUM(J12:J16) -> 107998 | ... N17: =SUM(N12:N16) -> 119744 | O17: =SUM(C17:N17) -> 8544013 | P17: =IFERROR(O17/O9-1,0) -> 0.062312411

Sheet Revenue
A1: REVENUE MODEL | Volume × NSP (FY24 Scenario Plan) | ₹ in Crores | B1: REVENUE MODEL | Volume × NSP (FY24 Scenario Plan) | ₹ in Crores | C1: REVENUE MODEL | Volume × NSP (FY24 Scenario Plan) | ₹ in Crores | D1: REVENUE MODEL | Volume × NSP (FY24 Scenario Plan) | ₹ in Crores | E1: REVENUE MODEL | Volume × NSP (FY24 Scenario Plan) | ₹ in Crores | F1: REVENUE MODEL | Volume × NSP (FY24 Scenario Plan) | ₹ in Crores | G1: REVENUE MODEL | Volume × NSP (FY24 Scenario Plan) | ₹ in Crores | H1: REVENUE MODEL | Volume × NSP (FY24 Scenario Plan) | ₹ in Crores | I1: REVENUE MODEL | Volume × NSP (FY24 Scenario Plan) | ₹ in Crores | J1: REVENUE MODEL | Volume × NSP (FY24 Scenario Plan) | ₹ in Crores | K1: REVENUE MODEL | Volume × NSP (FY24 Scenario Plan) | ₹ in Crores | L1: REVENUE MODEL | Volume × NSP (FY24 Scenario Plan) | ₹ in Crores | M1: REVENUE MODEL | Volume × NSP (FY24 Scenario Plan) | ₹ in Crores | N1: REVENUE MODEL | Volume × NSP (FY24 Scenario Plan) | ₹ in Crores | O1: REVENUE MODEL | Volume × NSP (FY24 Scenario Plan) | ₹ in Crores | P1: REVENUE MODEL | Volume × NSP (FY24 Scenario Plan) | ₹ in Crores
A2: Model Family | B2: Metric | C2: Apr | D2: May | E2: Jun | F2: Jul | G2: Aug | H2: Sep | I2: Oct | J2: Nov | K2: Dec | L2: Jan | M2: Feb | N2: Mar | O2: FY24 Total | P2: % of Total
A3: Bullet | B3: Volume (Units) | C3: =Volume_Plan!C12 -> 636000 | D3: =Volume_Plan!D12 -> 6678000 | E3: =Volume_Plan!E12 -> 50771 | F3: =Volume_Plan!F12 -> 62444 | G3: =Volume_Plan!G12 -> 51530 | H3: =Volume_Plan!H12 -> 50771 | I3: =Volume_Plan!I12 -> 62444 | J3: =Volume_Plan!J12 -> 51530 | ... O3: =Volume_Plan!O12 -> 7874555
B4: Adj NSP (₹) | C4: =Price_NSP!$I$3 -> 114411.36 | D4: =Price_NSP!$I$3 -> 114411.36 | E4: =Price_NSP!$I$3 -> 114411.36 | F4: =Price_NSP!$I$3 -> 114411.36 | G4: =Price_NSP!$I$3 -> 114411.36 | H4: =Price_NSP!$I$3 -> 114411.36 | I4: =Price_NSP!$I$3 -> 114411.36 | J4: =Price_NSP!$I$3 -> 114411.36 | ... O4: =Price_NSP!$I$3 -> 114411.36
B5: Gross Revenue (₹ Cr) | C5: =ROUND(C3*C4/10000000,2) -> 7276.56 | D5: =ROUND(D3*D4/10000000,2) -> 76403.91 | E5: =ROUND(E3*E4/10000000,2) -> 580.88 | F5: =ROUND(F3*F4/10000000,2) -> 714.43 | G5: =ROUND(G3*G4/10000000,2) -> 589.56 | H5: =ROUND(H3*H4/10000000,2) -> 580.88 | I5: =ROUND(I3*I4/10000000,2) -> 714.43 | J5: =ROUND(J3*J4/10000000,2) -> 589.56 | ... N5: =ROUND(N3*N4/10000000,2) -> 678.31 | O5: =SUM(C5:N5) -> 90093.86 | P5: =IFERROR(O5/O23,"-") -> 0.89199051
A7: Classic | B7: Volume (Units) | C7: =Volume_Plan!C13 -> 10428 | D7: =Volume_Plan!D13 -> 11548 | E7: =Volume_Plan!E13 -> 11549 | F7: =Volume_Plan!F13 -> 10428 | G7: =Volume_Plan!G13 -> 11548 | H7: =Volume_Plan!H13 -> 11549 | I7: =Volume_Plan!I13 -> 12220 | J7: =Volume_Plan!J13 -> 12351 | ... O7: =Volume_Plan!O13 -> 138592
B8: Adj NSP (₹) | C8: =Price_NSP!$I$4 -> 150099.12 | D8: =Price_NSP!$I$4 -> 150099.12 | E8: =Price_NSP!$I$4 -> 150099.12 | F8: =Price_NSP!$I$4 -> 150099.12 | G8: =Price_NSP!$I$4 -> 150099.12 | H8: =Price_NSP!$I$4 -> 150099.12 | I8: =Price_NSP!$I$4 -> 150099.12 | J8: =Price_NSP!$I$4 -> 150099.12 | ... O8: =Price_NSP!$I$4 -> 150099.12
B9: Gross Revenue (₹ Cr) | C9: =ROUND(C7*C8/10000000,2) -> 156.52 | D9: =ROUND(D7*D8/10000000,2) -> 173.33 | E9: =ROUND(E7*E8/10000000,2) -> 173.35 | F9: =ROUND(F7*F8/10000000,2) -> 156.52 | G9: =ROUND(G7*G8/10000000,2) -> 173.33 | H9: =ROUND(H7*H8/10000000,2) -> 173.35 | I9: =ROUND(I7*I8/10000000,2) -> 183.42 | J9: =ROUND(J7*J8/10000000,2) -> 185.39 | ... N9: =ROUND(N7*N8/10000000,2) -> 171.1 | O9: =SUM(C9:N9) -> 2080.24 | P9: =IFERROR(O9/O23,"-") -> 0.020595791
A11: Himalayan | B11: Volume (Units) | C11: =Volume_Plan!C14 -> 31315 | D11: =Volume_Plan!D14 -> 37685 | E11: =Volume_Plan!E14 -> 28241 | F11: =Volume_Plan!F14 -> 31315 | G11: =Volume_Plan!G14 -> 37685 | H11: =Volume_Plan!H14 -> 28241 | I11: =Volume_Plan!I14 -> 35577 | J11: =Volume_Plan!J14 -> 31868 | ... O11: =Volume_Plan!O14 -> 403292
B12: Adj NSP (₹) | C12: =Price_NSP!$I$6 -> 156785.57 | D12: =Price_NSP!$I$6 -> 156785.57 | E12: =Price_NSP!$I$6 -> 156785.57 | F12: =Price_NSP!$I$6 -> 156785.57 | G12: =Price_NSP!$I$6 -> 156785.57 | H12: =Price_NSP!$I$6 -> 156785.57 | I12: =Price_NSP!$I$6 -> 156785.57 | J12: =Price_NSP!$I$6 -> 156785.57 | ... O12: =Price_NSP!$I$6 -> 156785.57
B13: Gross Revenue (₹ Cr) | C13: =ROUND(C11*C12/10000000,2) -> 490.97 | D13: =ROUND(D11*D12/10000000,2) -> 590.85 | E13: =ROUND(E11*E12/10000000,2) -> 442.78 | F13: =ROUND(F11*F12/10000000,2) -> 490.97 | G13: =ROUND(G11*G12/10000000,2) -> 590.85 | H13: =ROUND(H11*H12/10000000,2) -> 442.78 | I13: =ROUND(I11*I12/10000000,2) -> 557.8 | J13: =ROUND(J11*J12/10000000,2) -> 499.64 | ... N13: =ROUND(N11*N12/10000000,2) -> 576.48 | O13: =SUM(C13:N13) -> 6323.04 | P13: =IFERROR(O13/O23,"-") -> 0.062602398
A15: Meteor | B15: Volume (Units) | C15: =Volume_Plan!C15 -> 2863 | D15: =Volume_Plan!D15 -> 5122 | E15: =Volume_Plan!E15 -> 4748 | F15: =Volume_Plan!F15 -> 2863 | G15: =Volume_Plan!G15 -> 5122 | H15: =Volume_Plan!H15 -> 4748 | I15: =Volume_Plan!I15 -> 4283 | J15: =Volume_Plan!J15 -> 3558 | ... O15: =Volume_Plan!O15 -> 45193
B16: Adj NSP (₹) | C16: =Price_NSP!$I$5 -> 155561.22 | D16: =Price_NSP!$I$5 -> 155561.22 | E16: =Price_NSP!$I$5 -> 155561.22 | F16: =Price_NSP!$I$5 -> 155561.22 | G16: =Price_NSP!$I$5 -> 155561.22 | H16: =Price_NSP!$I$5 -> 155561.22 | I16: =Price_NSP!$I$5 -> 155561.22 | J16: =Price_NSP!$I$5 -> 155561.22 | ... O16: =Price_NSP!$I$5 -> 155561.22
B17: Gross Revenue (₹ Cr) | C17: =ROUND(C15*C16/10000000,2) -> 44.54 | D17: =ROUND(D15*D16/10000000,2) -> 79.68 | E17: =ROUND(E15*E16/10000000,2) -> 73.86 | F17: =ROUND(F15*F16/10000000,2) -> 44.54 | G17: =ROUND(G15*G16/10000000,2) -> 79.68 | H17: =ROUND(H15*H16/10000000,2) -> 73.86 | I17: =ROUND(I15*I16/10000000,2) -> 66.63 | J17: =ROUND(J15*J16/10000000,2) -> 55.35 | ... N17: =ROUND(N15*N16/10000000,2) -> 49.55 | O17: =SUM(C17:N17) -> 703.05 | P17: =IFERROR(O17/O23,"-") -> 0.0069606733
A19: Twins | B19: Volume (Units) | C19: =Volume_Plan!C16 -> 5520 | D19: =Volume_Plan!D16 -> 7402 | E19: =Volume_Plan!E16 -> 5998 | F19: =Volume_Plan!F16 -> 5520 | G19: =Volume_Plan!G16 -> 7402 | H19: =Volume_Plan!H16 -> 5998 | I19: =Volume_Plan!I16 -> 4686 | J19: =Volume_Plan!J16 -> 8691 | ... O19: =Volume_Plan!O16 -> 82381
B20: Adj NSP (₹) | C20: =Price_NSP!$I$7 -> 218855.28 | D20: =Price_NSP!$I$7 -> 218855.28 | E20: =Price_NSP!$I$7 -> 218855.28 | F20: =Price_NSP!$I$7 -> 218855.28 | G20: =Price_NSP!$I$7 -> 218855.28 | H20: =Price_NSP!$I$7 -> 218855.28 | I20: =Price_NSP!$I$7 -> 218855.28 | J20: =Price_NSP!$I$7 -> 218855.28 | ... O20: =Price_NSP!$I$7 -> 218855.28
B21: Gross Revenue (₹ Cr) | C21: =ROUND(C19*C20/10000000,2) -> 120.81 | D21: =ROUND(D19*D20/10000000,2) -> 162 | E21: =ROUND(E19*E20/10000000,2) -> 131.27 | F21: =ROUND(F19*F20/10000000,2) -> 120.81 | G21: =ROUND(G19*G20/10000000,2) -> 162 | H21: =ROUND(H19*H20/10000000,2) -> 131.27 | I21: =ROUND(I19*I20/10000000,2) -> 102.56 | J21: =ROUND(J19*J20/10000000,2) -> 190.21 | ... N21: =ROUND(N19*N20/10000000,2) -> 199.25 | O21: =SUM(C21:N21) -> 1802.97 | P21: =IFERROR(O21/O23,"-") -> 0.01785063
A23: TOTAL GROSS REVENUE (₹ Cr) | B23: TOTAL GROSS REVENUE (₹ Cr) | C23: =C5+C9+C13+C17+C21 -> 8089.4 | D23: =D5+D9+D13+D17+D21 -> 77409.77 | E23: =E5+E9+E13+E17+E21 -> 1402.14 | F23: =F5+F9+F13+F17+F21 -> 1527.27 | G23: =G5+G9+G13+G17+G21 -> 1595.42 | H23: =H5+H9+H13+H17+H21 -> 1402.14 | I23: =I5+I9+I13+I17+I21 -> 1624.84 | J23: =J5+J9+J13+J17+J21 -> 1520.15 | ... N23: =N5+N9+N13+N17+N21 -> 1674.69 | O23: =SUM(C23:N23) -> 101003.16

Sheet Emp_Cost
A1: EMPLOYEE COST MODEL | Source: File 8 — India Headcount | ₹ in Crores | Rates illustrative — update with actual planning rates | B1: EMPLOYEE COST MODEL | Source: File 8 — India Headcount | ₹ in Crores | Rates illustrative — update with actual planning rates | C1: EMPLOYEE COST MODEL | Source: File 8 — India Headcount | ₹ in Crores | Rates illustrative — update with actual planning rates | D1: EMPLOYEE COST MODEL | Source: File 8 — India Headcount | ₹ in Crores | Rates illustrative — update with actual planning rates | E1: EMPLOYEE COST MODEL | Source: File 8 — India Headcount | ₹ in Crores | Rates illustrative — update with actual planning rates | F1: EMPLOYEE COST MODEL | Source: File 8 — India Headcount | ₹ in Crores | Rates illustrative — update with actual planning rates | G1: EMPLOYEE COST MODEL | Source: File 8 — India Headcount | ₹ in Crores | Rates illustrative — update with actual planning rates | H1: EMPLOYEE COST MODEL | Source: File 8 — India Headcount | ₹ in Crores | Rates illustrative — update with actual planning rates | I1: EMPLOYEE COST MODEL | Source: File 8 — India Headcount | ₹ in Crores | Rates illustrative — update with actual planning rates | J1: EMPLOYEE COST MODEL | Source: File 8 — India Headcount | ₹ in Crores | Rates illustrative — update with actual planning rates | K1: EMPLOYEE COST MODEL | Source: File 8 — India Headcount | ₹ in Crores | Rates illustrative — update with actual planning rates | L1: EMPLOYEE COST MODEL | Source: File 8 — India Headcount | ₹ in Crores | Rates illustrative — update with actual planning rates | M1: EMPLOYEE COST MODEL | Source: File 8 — India Headcount | ₹ in Crores | Rates illustrative — update with actual planning rates | N1: EMPLOYEE COST MODEL | Source: File 8 — India Headcount | ₹ in Crores | Rates illustrative — update with actual planning rates | O1: EMPLOYEE COST MODEL | Source: File 8 — India Headcount | ₹ in Crores | Rates illustrative — update with actual planning rates | P1: EMPLOYEE COST MODEL | Source: File 8 — India Headcount | ₹ in Crores | Rates illustrative — update with actual planning rates | Q1: EMPLOYEE COST MODEL | Source: File 8 — India Headcount | ₹ in Crores | Rates illustrative — update with actual planning rates | R1: EMPLOYEE COST MODEL | Source: File 8 — India Headcount | ₹ in Crores | Rates illustrative — update with actual planning rates
A2: Designation | B2: Function | C2: Opening HC | D2: Annual Rate (₹) | E2: PI % | F2: Apr-24 | G2: May-24 | H2: Jun-24 | I2: Jul-24 | J2: Aug-24 | K2: Sep-24 | L2: Oct-24 | M2: Nov-24 | N2: Dec-24 | O2: Jan-25 | P2: Feb-25 | Q2: Mar-25 | R2: FY24 Cost (₹Cr)
A3: Management | B3: Management Team | C3: 7 | D3: 6000000 | E3: 0.2 | F3: =ROUND(C3*D3*(1+E3)/12/10000000,3) -> 0.42 | G3: =ROUND(C3*D3*(1+E3)/12/10000000,3) -> 0.42 | H3: =ROUND(C3*D3*(1+E3)/12/10000000,3) -> 0.42 | I3: =ROUND(C3*D3*(1+E3)/12/10000000,3) -> 0.42 | J3: =ROUND(C3*D3*(1+E3)/12/10000000,3) -> 0.42 | K3: =ROUND(C3*D3*(1+E3)/12/10000000,3) -> 0.42 | L3: =ROUND(C3*D3*(1+E3)/12/10000000,3) -> 0.42 | M3: =ROUND(C3*D3*(1+E3)/12/10000000,3) -> 0.42 | N3: =ROUND(C3*D3*(1+E3)/12/10000000,3) -> 0.42 | O3: =ROUND(C3*D3*(1+E3)/12/10000000,3) -> 0.42 | P3: =ROUND(C3*D3*(1+E3)/12/10000000,3) -> 0.42 | Q3: =ROUND(C3*D3*(1+E3)/12/10000000,3) -> 0.42 | R3: =SUM(F3:Q3) -> 5.04
A4: Engineer / Executive | B4: Finance | C4: 2 | D4: 420000 | E4: 0.12 | F4: =ROUND(C4*D4*(1+E4)/12/10000000,3) -> 0.008 | G4: =ROUND(C4*D4*(1+E4)/12/10000000,3) -> 0.008 | H4: =ROUND(C4*D4*(1+E4)/12/10000000,3) -> 0.008 | I4: =ROUND(C4*D4*(1+E4)/12/10000000,3) -> 0.008 | J4: =ROUND(C4*D4*(1+E4)/12/10000000,3) -> 0.008 | K4: =ROUND(C4*D4*(1+E4)/12/10000000,3) -> 0.008 | L4: =ROUND(C4*D4*(1+E4)/12/10000000,3) -> 0.008 | M4: =ROUND(C4*D4*(1+E4)/12/10000000,3) -> 0.008 | N4: =ROUND(C4*D4*(1+E4)/12/10000000,3) -> 0.008 | O4: =ROUND(C4*D4*(1+E4)/12/10000000,3) -> 0.008 | P4: =ROUND(C4*D4*(1+E4)/12/10000000,3) -> 0.008 | Q4: =ROUND(C4*D4*(1+E4)/12/10000000,3) -> 0.008 | R4: =SUM(F4:Q4) -> 0.096
A5: Junior Executive | B5: Human Resources | C5: 1 | D5: 300000 | E5: 0.12 | F5: =ROUND(C5*D5*(1+E5)/12/10000000,3) -> 0.003 | G5: =ROUND(C5*D5*(1+E5)/12/10000000,3) -> 0.003 | H5: =ROUND(C5*D5*(1+E5)/12/10000000,3) -> 0.003 | I5: =ROUND(C5*D5*(1+E5)/12/10000000,3) -> 0.003 | J5: =ROUND(C5*D5*(1+E5)/12/10000000,3) -> 0.003 | K5: =ROUND(C5*D5*(1+E5)/12/10000000,3) -> 0.003 | L5: =ROUND(C5*D5*(1+E5)/12/10000000,3) -> 0.003 | M5: =ROUND(C5*D5*(1+E5)/12/10000000,3) -> 0.003 | N5: =ROUND(C5*D5*(1+E5)/12/10000000,3) -> 0.003 | O5: =ROUND(C5*D5*(1+E5)/12/10000000,3) -> 0.003 | P5: =ROUND(C5*D5*(1+E5)/12/10000000,3) -> 0.003 | Q5: =ROUND(C5*D5*(1+E5)/12/10000000,3) -> 0.003 | R5: =SUM(F5:Q5) -> 0.036
A6: GET/PGET/MT | B6: Information Technology | C6: 1 | D6: 240000 | F6: =ROUND(C6*D6*(1+E6)/12/10000000,3) -> 0.002 | G6: =ROUND(C6*D6*(1+E6)/12/10000000,3) -> 0.002 | H6: =ROUND(C6*D6*(1+E6)/12/10000000,3) -> 0.002 | I6: =ROUND(C6*D6*(1+E6)/12/10000000,3) -> 0.002 | J6: =ROUND(C6*D6*(1+E6)/12/10000000,3) -> 0.002 | K6: =ROUND(C6*D6*(1+E6)/12/10000000,3) -> 0.002 | L6: =ROUND(C6*D6*(1+E6)/12/10000000,3) -> 0.002 | M6: =ROUND(C6*D6*(1+E6)/12/10000000,3) -> 0.002 | N6: =ROUND(C6*D6*(1+E6)/12/10000000,3) -> 0.002 | O6: =ROUND(C6*D6*(1+E6)/12/10000000,3) -> 0.002 | P6: =ROUND(C6*D6*(1+E6)/12/10000000,3) -> 0.002 | Q6: =ROUND(C6*D6*(1+E6)/12/10000000,3) -> 0.002 | R6: =SUM(F6:Q6) -> 0.024
A7: Workmen | B7: Product Strategy & Industrial Design | C7: 3 | D7: 180000 | E7: 0.12 | F7: =ROUND(C7*D7*(1+E7)/12/10000000,3) -> 0.005 | G7: =ROUND(C7*D7*(1+E7)/12/10000000,3) -> 0.005 | H7: =ROUND(C7*D7*(1+E7)/12/10000000,3) -> 0.005 | I7: =ROUND(C7*D7*(1+E7)/12/10000000,3) -> 0.005 | J7: =ROUND(C7*D7*(1+E7)/12/10000000,3) -> 0.005 | K7: =ROUND(C7*D7*(1+E7)/12/10000000,3) -> 0.005 | L7: =ROUND(C7*D7*(1+E7)/12/10000000,3) -> 0.005 | M7: =ROUND(C7*D7*(1+E7)/12/10000000,3) -> 0.005 | N7: =ROUND(C7*D7*(1+E7)/12/10000000,3) -> 0.005 | O7: =ROUND(C7*D7*(1+E7)/12/10000000,3) -> 0.005 | P7: =ROUND(C7*D7*(1+E7)/12/10000000,3) -> 0.005 | Q7: =ROUND(C7*D7*(1+E7)/12/10000000,3) -> 0.005 | R7: =SUM(F7:Q7) -> 0.06
A8: Associate Engineers | B8: Apparel | C8: 5 | D8: 216000 | E8: 0.055 | F8: =ROUND(C8*D8*(1+E8)/12/10000000,3) -> 0.009 | G8: =ROUND(C8*D8*(1+E8)/12/10000000,3) -> 0.009 | H8: =ROUND(C8*D8*(1+E8)/12/10000000,3) -> 0.009 | I8: =ROUND(C8*D8*(1+E8)/12/10000000,3) -> 0.009 | J8: =ROUND(C8*D8*(1+E8)/12/10000000,3) -> 0.009 | K8: =ROUND(C8*D8*(1+E8)/12/10000000,3) -> 0.009 | L8: =ROUND(C8*D8*(1+E8)/12/10000000,3) -> 0.009 | M8: =ROUND(C8*D8*(1+E8)/12/10000000,3) -> 0.009 | N8: =ROUND(C8*D8*(1+E8)/12/10000000,3) -> 0.009 | O8: =ROUND(C8*D8*(1+E8)/12/10000000,3) -> 0.009 | P8: =ROUND(C8*D8*(1+E8)/12/10000000,3) -> 0.009 | Q8: =ROUND(C8*D8*(1+E8)/12/10000000,3) -> 0.009 | R8: =SUM(F8:Q8) -> 0.108
A9: Testing Engineers | B9: Business-Genuine Motor Cycle Accessories | C9: 4 | D9: 264000 | F9: =ROUND(C9*D9*(1+E9)/12/10000000,3) -> 0.009 | G9: =ROUND(C9*D9*(1+E9)/12/10000000,3) -> 0.009 | H9: =ROUND(C9*D9*(1+E9)/12/10000000,3) -> 0.009 | I9: =ROUND(C9*D9*(1+E9)/12/10000000,3) -> 0.009 | J9: =ROUND(C9*D9*(1+E9)/12/10000000,3) -> 0.009 | K9: =ROUND(C9*D9*(1+E9)/12/10000000,3) -> 0.009 | L9: =ROUND(C9*D9*(1+E9)/12/10000000,3) -> 0.009 | M9: =ROUND(C9*D9*(1+E9)/12/10000000,3) -> 0.009 | N9: =ROUND(C9*D9*(1+E9)/12/10000000,3) -> 0.009 | O9: =ROUND(C9*D9*(1+E9)/12/10000000,3) -> 0.009 | P9: =ROUND(C9*D9*(1+E9)/12/10000000,3) -> 0.009 | Q9: =ROUND(C9*D9*(1+E9)/12/10000000,3) -> 0.009 | R9: =SUM(F9:Q9) -> 0.108
A10: NAPS Trainee | B10: Spare Parts Business | C10: 4 | D10: 96000 | F10: =ROUND(C10*D10*(1+E10)/12/10000000,3) -> 0.003 | G10: =ROUND(C10*D10*(1+E10)/12/10000000,3) -> 0.003 | H10: =ROUND(C10*D10*(1+E10)/12/10000000,3) -> 0.003 | I10: =ROUND(C10*D10*(1+E10)/12/10000000,3) -> 0.003 | J10: =ROUND(C10*D10*(1+E10)/12/10000000,3) -> 0.003 | K10: =ROUND(C10*D10*(1+E10)/12/10000000,3) -> 0.003 | L10: =ROUND(C10*D10*(1+E10)/12/10000000,3) -> 0.003 | M10: =ROUND(C10*D10*(1+E10)/12/10000000,3) -> 0.003 | N10: =ROUND(C10*D10*(1+E10)/12/10000000,3) -> 0.003 | O10: =ROUND(C10*D10*(1+E10)/12/10000000,3) -> 0.003 | P10: =ROUND(C10*D10*(1+E10)/12/10000000,3) -> 0.003 | Q10: =ROUND(C10*D10*(1+E10)/12/10000000,3) -> 0.003 | R10: =SUM(F10:Q10) -> 0.036
A11: NEEM Trainee | B11: Electric Vehicles (BD) | C11: 5 | D11: 96000 | F11: =ROUND(C11*D11*(1+E11)/12/10000000,3) -> 0.004 | G11: =ROUND(C11*D11*(1+E11)/12/10000000,3) -> 0.004 | H11: =ROUND(C11*D11*(1+E11)/12/10000000,3) -> 0.004 | I11: =ROUND(C11*D11*(1+E11)/12/10000000,3) -> 0.004 | J11: =ROUND(C11*D11*(1+E11)/12/10000000,3) -> 0.004 | K11: =ROUND(C11*D11*(1+E11)/12/10000000,3) -> 0.004 | L11: =ROUND(C11*D11*(1+E11)/12/10000000,3) -> 0.004 | M11: =ROUND(C11*D11*(1+E11)/12/10000000,3) -> 0.004 | N11: =ROUND(C11*D11*(1+E11)/12/10000000,3) -> 0.004 | O11: =ROUND(C11*D11*(1+E11)/12/10000000,3) -> 0.004 | P11: =ROUND(C11*D11*(1+E11)/12/10000000,3) -> 0.004 | Q11: =ROUND(C11*D11*(1+E11)/12/10000000,3) -> 0.004 | R11: =SUM(F11:Q11) -> 0.048
A12: Casuals-Direct | B12: Brand | C12: 3 | D12: 144000 | F12: =ROUND(C12*D12*(1+E12)/12/10000000,3) -> 0.004 | G12: =ROUND(C12*D12*(1+E12)/12/10000000,3) -> 0.004 | H12: =ROUND(C12*D12*(1+E12)/12/10000000,3) -> 0.004 | I12: =ROUND(C12*D12*(1+E12)/12/10000000,3) -> 0.004 | J12: =ROUND(C12*D12*(1+E12)/12/10000000,3) -> 0.004 | K12: =ROUND(C12*D12*(1+E12)/12/10000000,3) -> 0.004 | L12: =ROUND(C12*D12*(1+E12)/12/10000000,3) -> 0.004 | M12: =ROUND(C12*D12*(1+E12)/12/10000000,3) -> 0.004 | N12: =ROUND(C12*D12*(1+E12)/12/10000000,3) -> 0.004 | O12: =ROUND(C12*D12*(1+E12)/12/10000000,3) -> 0.004 | P12: =ROUND(C12*D12*(1+E12)/12/10000000,3) -> 0.004 | Q12: =ROUND(C12*D12*(1+E12)/12/10000000,3) -> 0.004 | R12: =SUM(F12:Q12) -> 0.048
A13: Staff on Contract | B13: Quality and Projects & ME | C13: 1 | D13: 300000 | F13: =ROUND(C13*D13*(1+E13)/12/10000000,3) -> 0.003 | G13: =ROUND(C13*D13*(1+E13)/12/10000000,3) -> 0.003 | H13: =ROUND(C13*D13*(1+E13)/12/10000000,3) -> 0.003 | I13: =ROUND(C13*D13*(1+E13)/12/10000000,3) -> 0.003 | J13: =ROUND(C13*D13*(1+E13)/12/10000000,3) -> 0.003 | K13: =ROUND(C13*D13*(1+E13)/12/10000000,3) -> 0.003 | L13: =ROUND(C13*D13*(1+E13)/12/10000000,3) -> 0.003 | M13: =ROUND(C13*D13*(1+E13)/12/10000000,3) -> 0.003 | N13: =ROUND(C13*D13*(1+E13)/12/10000000,3) -> 0.003 | O13: =ROUND(C13*D13*(1+E13)/12/10000000,3) -> 0.003 | P13: =ROUND(C13*D13*(1+E13)/12/10000000,3) -> 0.003 | Q13: =ROUND(C13*D13*(1+E13)/12/10000000,3) -> 0.003 | R13: =SUM(F13:Q13) -> 0.036
A14: TOTAL EMPLOYEE COST (₹ Cr) | B14: TOTAL EMPLOYEE COST (₹ Cr) | C14: TOTAL EMPLOYEE COST (₹ Cr) | D14: TOTAL EMPLOYEE COST (₹ Cr) | E14: TOTAL EMPLOYEE COST (₹ Cr) | F14: =SUM(F3:F13) -> 0.47 | G14: =SUM(G3:G13) -> 0.47 | H14: =SUM(H3:H13) -> 0.47 | I14: =SUM(I3:I13) -> 0.47 | J14: =SUM(J3:J13) -> 0.47 | K14: =SUM(K3:K13) -> 0.47 | L14: =SUM(L3:L13) -> 0.47 | M14: =SUM(M3:M13) -> 0.47 | ... R14: =SUM(R3:R13) -> 5.64

Sheet Mktng_Cost
A1: MARKETING COST PLAN | Source: File 4 — Marketing Cost Master | ₹ in Crores | B1: MARKETING COST PLAN | Source: File 4 — Marketing Cost Master | ₹ in Crores | C1: MARKETING COST PLAN | Source: File 4 — Marketing Cost Master | ₹ in Crores | D1: MARKETING COST PLAN | Source: File 4 — Marketing Cost Master | ₹ in Crores | E1: MARKETING COST PLAN | Source: File 4 — Marketing Cost Master | ₹ in Crores | F1: MARKETING COST PLAN | Source: File 4 — Marketing Cost Master | ₹ in Crores | G1: MARKETING COST PLAN | Source: File 4 — Marketing Cost Master | ₹ in Crores | H1: MARKETING COST PLAN | Source: File 4 — Marketing Cost Master | ₹ in Crores | I1: MARKETING COST PLAN | Source: File 4 — Marketing Cost Master | ₹ in Crores | J1: MARKETING COST PLAN | Source: File 4 — Marketing Cost Master | ₹ in Crores | K1: MARKETING COST PLAN | Source: File 4 — Marketing Cost Master | ₹ in Crores | L1: MARKETING COST PLAN | Source: File 4 — Marketing Cost Master | ₹ in Crores | M1: MARKETING COST PLAN | Source: File 4 — Marketing Cost Master | ₹ in Crores | N1: MARKETING COST PLAN | Source: File 4 — Marketing Cost Master | ₹ in Crores | O1: MARKETING COST PLAN | Source: File 4 — Marketing Cost Master | ₹ in Crores | P1: MARKETING COST PLAN | Source: File 4 — Marketing Cost Master | ₹ in Crores | Q1: MARKETING COST PLAN | Source: File 4 — Marketing Cost Master | ₹ in Crores | R1: MARKETING COST PLAN | Source: File 4 — Marketing Cost Master | ₹ in Crores
A2: IO Reference | B2: Activity Name | C2: Model Family | D2: MIS Heading | E2: Cost Center | F2: Type | G2: Apr-24 | H2: May-24 | I2: Jun-24 | J2: Jul-24 | K2: Aug-24 | L2: Sep-24 | M2: Oct-24 | N2: Nov-24 | O2: Dec-24 | P2: Jan-25 | Q2: Feb-25 | R2: Mar-25 | S2: FY24 Total (₹Cr)
A3: IO-001 | B3: Digital Marketing - Social Media | C3: Bullet | D3: Digital Media | E3: CC-MKT-01 | F3: ATL | G3: 0.4 | H3: 0.5 | I3: 0.4 | J3: 0.56 | K3: 0.64 | L3: 0.5 | M3: 0.6 | N3: 0.56 | O3: 0.4 | P3: 0.44 | Q3: 0.5 | R3: 0.6 | S3: =SUM(G3:R3) -> 6.1
A4: IO-002 | B4: Digital Marketing - Influencer | C4: Classic | D4: Digital Media | E4: CC-MKT-01 | F4: BTL | G4: 0.36 | H4: 0.45 | I4: 0.36 | J4: 0.5 | K4: 0.58 | L4: 0.45 | M4: 0.54 | N4: 0.5 | O4: 0.36 | P4: 0.4 | Q4: 0.45 | R4: 0.54 | S4: =SUM(G4:R4) -> 5.49
A5: IO-003 | B5: Outdoor/OOH Advertising | C5: Meteor | D5: OOH | E5: CC-MKT-02 | F5: ATL | G5: 0.16 | H5: 0.2 | I5: 0.16 | J5: 0.22 | K5: 0.26 | L5: 0.2 | M5: 0.24 | N5: 0.22 | O5: 0.16 | P5: 0.18 | Q5: 0.2 | R5: 0.24 | S5: =SUM(G5:R5) -> 2.44
A6: IO-004 | B6: Dealership Events & Activations | C6: Himalayan | D6: Events | E6: CC-MKT-03 | F6: BTL | G6: 0.24 | H6: 0.3 | I6: 0.24 | J6: 0.34 | K6: 0.38 | L6: 0.3 | M6: 0.36 | N6: 0.34 | O6: 0.24 | P6: 0.26 | Q6: 0.3 | R6: 0.36 | S6: =SUM(G6:R6) -> 3.66
A7: IO-005 | B7: Product Launch Campaign | C7: Twins | D7: Launch | E7: CC-MKT-04 | F7: ATL | G7: 0.2 | H7: 0.25 | I7: 0.2 | J7: 0.28 | K7: 0.32 | L7: 0.25 | M7: 0.3 | N7: 0.28 | O7: 0.2 | P7: 0.22 | Q7: 0.25 | R7: 0.3 | S7: =SUM(G7:R7) -> 3.05
A8: IO-006 | B8: Sports Sponsorships | C8: All | D8: Sponsorship | E8: CC-MKT-05 | F8: ATL | G8: 0.16 | H8: 0.2 | I8: 0.16 | J8: 0.22 | K8: 0.26 | L8: 0.2 | M8: 0.24 | N8: 0.22 | O8: 0.16 | P8: 0.18 | Q8: 0.2 | R8: 0.24 | S8: =SUM(G8:R8) -> 2.44
A9: IO-007 | B9: Riding Community / RE Community | C9: All | D9: Community | E9: CC-MKT-06 | F9: BTL | G9: 0.14 | H9: 0.18 | I9: 0.14 | J9: 0.2 | K9: 0.22 | L9: 0.18 | M9: 0.21 | N9: 0.2 | O9: 0.14 | P9: 0.15 | Q9: 0.18 | R9: 0.21 | S9: =SUM(G9:R9) -> 2.15
A10: IO-008 | B10: Trade Promotions & Dealer Incentives | C10: All | D10: Trade Promo | E10: CC-MKT-07 | F10: BTL | G10: 0.16 | H10: 0.2 | I10: 0.16 | J10: 0.22 | K10: 0.26 | L10: 0.2 | M10: 0.24 | N10: 0.22 | O10: 0.16 | P10: 0.18 | Q10: 0.2 | R10: 0.24 | S10: =SUM(G10:R10) -> 2.44
A11: IO-009 | B11: Market Research | C11: All | D11: Research | E11: CC-MKT-08 | F11: Below Line | G11: 0.06 | H11: 0.07 | I11: 0.06 | J11: 0.08 | K11: 0.1 | L11: 0.07 | M11: 0.09 | N11: 0.08 | O11: 0.06 | P11: 0.07 | Q11: 0.07 | R11: 0.09 | S11: =SUM(G11:R11) -> 0.9
A12: IO-010 | B12: PR & Corporate Communications | C12: All | D12: PR | E12: CC-MKT-09 | F12: ATL | G12: 0.12 | H12: 0.15 | I12: 0.12 | J12: 0.17 | K12: 0.19 | L12: 0.15 | M12: 0.18 | N12: 0.17 | O12: 0.12 | P12: 0.13 | Q12: 0.15 | R12: 0.18 | S12: =SUM(G12:R12) -> 1.83
A13: TOTAL MARKETING COST (₹ Cr) | B13: TOTAL MARKETING COST (₹ Cr) | C13: TOTAL MARKETING COST (₹ Cr) | D13: TOTAL MARKETING COST (₹ Cr) | E13: TOTAL MARKETING COST (₹ Cr) | F13: TOTAL MARKETING COST (₹ Cr) | G13: =SUM(G3:G12) -> 2 | H13: =SUM(H3:H12) -> 2.5 | I13: =SUM(I3:I12) -> 2 | J13: =SUM(J3:J12) -> 2.79 | K13: =SUM(K3:K12) -> 3.21 | L13: =SUM(L3:L12) -> 2.5 | M13: =SUM(M3:M12) -> 3 | N13: =SUM(N3:N12) -> 2.79 | ... S13: =SUM(S3:S12) -> 30.5

Sheet GL_Reference
A1: GL HIERARCHY REFERENCE | Source: Files 9 & 10 — Chart of Accounts, GL Mapping | B1: GL HIERARCHY REFERENCE | Source: Files 9 & 10 — Chart of Accounts, GL Mapping | C1: GL HIERARCHY REFERENCE | Source: Files 9 & 10 — Chart of Accounts, GL Mapping | D1: GL HIERARCHY REFERENCE | Source: Files 9 & 10 — Chart of Accounts, GL Mapping | E1: GL HIERARCHY REFERENCE | Source: Files 9 & 10 — Chart of Accounts, GL Mapping | F1: GL HIERARCHY REFERENCE | Source: Files 9 & 10 — Chart of Accounts, GL Mapping | G1: GL HIERARCHY REFERENCE | Source: Files 9 & 10 — Chart of Accounts, GL Mapping | H1: GL HIERARCHY REFERENCE | Source: Files 9 & 10 — Chart of Accounts, GL Mapping
A2: ▶ CHART OF ACCOUNTS (GL Master) | B2: ▶ CHART OF ACCOUNTS (GL Master) | C2: ▶ CHART OF ACCOUNTS (GL Master) | E2: ▶ P&L HIERARCHY (GL → P&L Node) | F2: ▶ P&L HIERARCHY (GL → P&L Node) | G2: ▶ P&L HIERARCHY (GL → P&L Node) | H2: ▶ P&L HIERARCHY (GL → P&L Node)
A3: G/L Account | B3: Description | C3: B/S or P&L | E3: GL From | F3: GL To | G3: P&L Node (Parent1) | H3: P&L Node (Parent2)
A4: 100000 | B4: EQUITY SHARE CAPITAL | C4: X | E4: 760300 | F4: 760300 | G4: EXCISE DUTY -SUBCONTRACTING | H4: EXCISE DUTY
A5: 100001 | B5: EQUITY SHARE CAPITAL SUSPENSE ACCOUNT | C5: X | E5: 760600 | F5: 760600 | G5: SCRAP SALES | H5: MATERIAL COST
A6: 100002 | B6: Gratuity Fund | C6: X | E6: 473501 | F6: 473501 | G6: VEHICLES | H6: MATERIAL CONSUMED
A7: 114300 | B7: GENERAL RESERVE | C7: X | E7: 503305 | F7: 503305 | G7: VEHICLES | H7: MATERIAL CONSUMED
A8: 114310 | B8: Depreciation Reserve | C8: X | E8: 503320 | F8: 503320 | G8: VEHICLES | H8: MATERIAL CONSUMED
A9: 114320 | B9: ESOP-Equity Reserve | C9: X | E9: 503400 | F9: 503400 | G9: VEHICLES | H9: MATERIAL CONSUMED
A10: 114400 | B10: PROFIT & LOSS ACCOUNT | C10: X | E10: 504100 | F10: 504100 | G10: VEHICLES | H10: MATERIAL CONSUMED
A11: 114500 | B11: RETAINED EARNING (CURRENT YEAR PROFIT) | C11: X | E11: 504105 | F11: 504105 | G11: VEHICLES | H11: MATERIAL CONSUMED
A12: 214510 | B12: Motorcycle revenue india | E12: 504200 | F12: 504200 | G12: VEHICLES | H12: MATERIAL CONSUMED
A13: 214511 | B13: Spares revenue india | E13: 621101 | F13: 621101 | G13: Rates & Taxes | H13: FIXED OVERHEADS
A14: 214513 | B14: Motorcycle material cost india | E14: 412013 | F14: 412013 | G14: DOMESTIC/EXPORTS ACCESSORIES | H14: SALES
A15: 214513 | B15: Motorcycle other costs india | E15: 412014 | F15: 412014 | G15: DOMESTIC/EXPORTS ACCESSORIES | H15: SALES
E16: 687001 | F16: 687001 | G16: OTHER INCOME | H16: OTHERS
E17: 9687001 | F17: 9687001 | G17: OTHER INCOME | H17: OTHERS
E18: 375180 | F18: 375180 | G18: EXCISE DUTY- VEHICLES | H18: EXCISE DUTY
E19: 760000 | F19: 760000 | G19: EXCISE DUTY- VEHICLES | H19: EXCISE DUTY
E20: 760050 | F20: 760050 | G20: EXCISE DUTY- VEHICLES | H20: EXCISE DUTY
E21: 375063 | F21: 375063 | G21: EXCISE DUTY - SPARES | H21: EXCISE DUTY
E22: 760100 | F22: 760100 | G22: EXCISE DUTY - SPARES | H22: EXCISE DUTY
E23: 760350 | F23: 760350 | G23: EXCISE DUTY - ACCESSORIES | H23: EXCISE DUTY

Sheet P&L
A1: P&L SUMMARY | FY24 SCENARIO PLAN | Change scenario on Assumptions tab | Rs. in Crores | B1: P&L SUMMARY | FY24 SCENARIO PLAN | Change scenario on Assumptions tab | Rs. in Crores | C1: P&L SUMMARY | FY24 SCENARIO PLAN | Change scenario on Assumptions tab | Rs. in Crores | D1: P&L SUMMARY | FY24 SCENARIO PLAN | Change scenario on Assumptions tab | Rs. in Crores | E1: P&L SUMMARY | FY24 SCENARIO PLAN | Change scenario on Assumptions tab | Rs. in Crores | F1: P&L SUMMARY | FY24 SCENARIO PLAN | Change scenario on Assumptions tab | Rs. in Crores | G1: P&L SUMMARY | FY24 SCENARIO PLAN | Change scenario on Assumptions tab | Rs. in Crores | H1: P&L SUMMARY | FY24 SCENARIO PLAN | Change scenario on Assumptions tab | Rs. in Crores | I1: P&L SUMMARY | FY24 SCENARIO PLAN | Change scenario on Assumptions tab | Rs. in Crores | J1: P&L SUMMARY | FY24 SCENARIO PLAN | Change scenario on Assumptions tab | Rs. in Crores | K1: P&L SUMMARY | FY24 SCENARIO PLAN | Change scenario on Assumptions tab | Rs. in Crores | L1: P&L SUMMARY | FY24 SCENARIO PLAN | Change scenario on Assumptions tab | Rs. in Crores | M1: P&L SUMMARY | FY24 SCENARIO PLAN | Change scenario on Assumptions tab | Rs. in Crores | N1: P&L SUMMARY | FY24 SCENARIO PLAN | Change scenario on Assumptions tab | Rs. in Crores | O1: P&L SUMMARY | FY24 SCENARIO PLAN | Change scenario on Assumptions tab | Rs. in Crores | P1: P&L SUMMARY | FY24 SCENARIO PLAN | Change scenario on Assumptions tab | Rs. in Crores
A2: P&L Line Item | B2: P&L Line Item | C2: Apr-24 | D2: May-24 | E2: Jun-24 | F2: Jul-24 | G2: Aug-24 | H2: Sep-24 | I2: Oct-24 | J2: Nov-24 | K2: Dec-24 | L2: Jan-25 | M2: Feb-25 | N2: Mar-25 | O2: FY24 Total | P2: % of Rev
A3: REVENUE | B3: REVENUE
A4: Gross Revenue | B4: Gross Revenue | C4: =Revenue!C23 -> 8089.4 | D4: =Revenue!D23 -> 77409.77 | E4: =Revenue!E23 -> 1402.14 | F4: =Revenue!F23 -> 1527.27 | G4: =Revenue!G23 -> 1595.42 | H4: =Revenue!H23 -> 1402.14 | I4: =Revenue!I23 -> 1624.84 | J4: =Revenue!J23 -> 1520.15 | ... N4: =Revenue!N23 -> 1674.69 | O4: =SUM(C4:N4) -> 101003.16 | P4: =IFERROR(O4/O4,"-") -> 1
A5: Less: Trade Discounts & Returns | B5: Less: Trade Discounts & Returns | C5: =ROUND(C4*0.01,2) -> 80.89 | D5: =ROUND(D4*0.01,2) -> 774.1 | E5: =ROUND(E4*0.01,2) -> 14.02 | F5: =ROUND(F4*0.01,2) -> 15.27 | G5: =ROUND(G4*0.01,2) -> 15.95 | H5: =ROUND(H4*0.01,2) -> 14.02 | I5: =ROUND(I4*0.01,2) -> 16.25 | J5: =ROUND(J4*0.01,2) -> 15.2 | ... N5: =ROUND(N4*0.01,2) -> 16.75 | O5: =SUM(C5:N5) -> 1010.02 | P5: =IFERROR(O5/O4,"-") -> 0.0099998852
A6: NET REVENUE | B6: NET REVENUE | C6: =C4-C5 -> 8008.51 | D6: =D4-D5 -> 76635.67 | E6: =E4-E5 -> 1388.12 | F6: =F4-F5 -> 1512 | G6: =G4-G5 -> 1579.47 | H6: =H4-H5 -> 1388.12 | I6: =I4-I5 -> 1608.59 | J6: =J4-J5 -> 1504.95 | ... N6: =N4-N5 -> 1657.94 | O6: =SUM(C6:N6) -> 99993.14 | P6: =IFERROR(O6/O4,"-") -> 0.99000011
A8: COST OF GOODS SOLD | B8: COST OF GOODS SOLD | C8: COST OF GOODS SOLD | D8: COST OF GOODS SOLD | E8: COST OF GOODS SOLD | F8: COST OF GOODS SOLD | G8: COST OF GOODS SOLD | H8: COST OF GOODS SOLD | I8: COST OF GOODS SOLD | J8: COST OF GOODS SOLD | K8: COST OF GOODS SOLD | L8: COST OF GOODS SOLD | M8: COST OF GOODS SOLD | N8: COST OF GOODS SOLD | O8: COST OF GOODS SOLD | P8: COST OF GOODS SOLD
A9: Material & Vehicle Cost | B9: Material & Vehicle Cost | C9: =ROUND(C6*Assumptions!$E$24,2) -> 4805.11 | D9: =ROUND(D6*Assumptions!$E$24,2) -> 45981.4 | E9: =ROUND(E6*Assumptions!$E$24,2) -> 832.87 | F9: =ROUND(F6*Assumptions!$E$24,2) -> 907.2 | G9: =ROUND(G6*Assumptions!$E$24,2) -> 947.68 | H9: =ROUND(H6*Assumptions!$E$24,2) -> 832.87 | I9: =ROUND(I6*Assumptions!$E$24,2) -> 965.15 | J9: =ROUND(J6*Assumptions!$E$24,2) -> 902.97 | ... N9: =ROUND(N6*Assumptions!$E$24,2) -> 994.76 | O9: =SUM(C9:N9) -> 59995.87 | P9: =IFERROR(O9/O6,"-") -> 0.59999986
A10: GROSS PROFIT | B10: GROSS PROFIT | C10: =C6-C9 -> 3203.4 | D10: =D6-D9 -> 30654.27 | E10: =E6-E9 -> 555.25 | F10: =F6-F9 -> 604.8 | G10: =G6-G9 -> 631.79 | H10: =H6-H9 -> 555.25 | I10: =I6-I9 -> 643.44 | J10: =J6-J9 -> 601.98 | ... N10: =N6-N9 -> 663.18 | O10: =SUM(C10:N10) -> 39997.27 | P10: =IFERROR(O10/O4,"-") -> 0.39600018
A12: OPERATING EXPENSES | B12: OPERATING EXPENSES | C12: OPERATING EXPENSES | D12: OPERATING EXPENSES | E12: OPERATING EXPENSES | F12: OPERATING EXPENSES | G12: OPERATING EXPENSES | H12: OPERATING EXPENSES | I12: OPERATING EXPENSES | J12: OPERATING EXPENSES | K12: OPERATING EXPENSES | L12: OPERATING EXPENSES | M12: OPERATING EXPENSES | N12: OPERATING EXPENSES | O12: OPERATING EXPENSES | P12: OPERATING EXPENSES
